import{_ as m}from"./ValaxyMain.vue_vue_type_style_index_0_lang.DXFDIcRI.js";import{f,a as x,u as b}from"./chunks/vue-router.CE6eJGTm.js";import{O as y,a4 as e,V as t,U as a,X as n,u as v,P as E,A as k}from"./framework.CgPPQfmH.js";import"./app.2Hk-Pb-P.js";import"./chunks/dayjs.CCYrSalk.js";import"./chunks/vue-i18n.BoM8szIi.js";import"./chunks/pinia.BjFmakTL.js";import"./chunks/@vueuse/motion.Cp--YhDB.js";import"./chunks/nprogress.BahbDzmd.js";import"./YunComment.vue_vue_type_style_index_0_lang.DC8N30BB.js";import"./index.C5okkQwF.js";import"./YunPageHeader.vue_vue_type_script_setup_true_lang.PEAAi8W5.js";import"./post.CGlAV6UI.js";const _=f("/posts/study notes/java base knowledge/java 异常",async o=>JSON.parse('{"title":"java 异常","description":"","frontmatter":{"title":"java 异常","date":"2025-04-19","updated":"2025-04-19","categories":"java","tags":["java","笔记"],"top":1},"headers":[{"level":3,"title":"1、Error和Exception 区别","slug":"_1、error和exception-区别","link":"#_1、error和exception-区别","children":[]},{"level":3,"title":"2、常见的异常类","slug":"_2、常见的异常类","link":"#_2、常见的异常类","children":[]},{"level":3,"title":"3 、throw和throws的区别","slug":"_3-、throw和throws的区别","link":"#_3-、throw和throws的区别","children":[]},{"level":3,"title":"4、finally相关问题","slug":"_4、finally相关问题","link":"#_4、finally相关问题","children":[]},{"level":3,"title":"5、异常处理过程","slug":"_5、异常处理过程","link":"#_5、异常处理过程","children":[]},{"level":3,"title":"6、外中断和异常的区别","slug":"_6、外中断和异常的区别","link":"#_6、外中断和异常的区别","children":[]}],"relativePath":"pages/posts/study notes/java base knowledge/java 异常.md","lastUpdated":1745542762000}'),{lazy:(o,i)=>o.name===i.name}),V={__name:"java 异常",setup(o,{expose:i}){var u;const{data:s}=_(),h=b(),p=x(),r=Object.assign(p.meta.frontmatter||{},((u=s.value)==null?void 0:u.frontmatter)||{});return p.meta.frontmatter=r,h.currentRoute.value.data=s.value,k("valaxy:frontmatter",r),globalThis.$frontmatter=r,i({frontmatter:{title:"java 异常",date:"2025-04-19",updated:"2025-04-19",categories:"java",tags:["java","笔记"],top:1}}),(l,c)=>{const d=m;return E(),y(d,{frontmatter:v(r)},{"main-content-md":e(()=>c[0]||(c[0]=[a("h1",{id:"异常",tabindex:"-1"},[n("异常 "),a("a",{class:"header-anchor",href:"#异常","aria-label":'Permalink to "异常"'},"​")],-1),a("h3",{id:"_1、error和exception-区别",tabindex:"-1"},[n("1、Error和Exception 区别 "),a("a",{class:"header-anchor",href:"#_1、error和exception-区别","aria-label":'Permalink to "1、Error和Exception 区别"'},"​")],-1),a("p",null,"Error类和Exception类的父类都是Throwable类",-1),a("h4",{id:"error类",tabindex:"-1"},[n("Error类 "),a("a",{class:"header-anchor",href:"#error类","aria-label":'Permalink to "Error类"'},"​")],-1),a("p",null,"一般是系统、jvm的问题。",-1),a("p",null,"如：系统崩溃、虚拟机错误、内存空间不足、方法调用栈溢出（stackoverflow）、堆内存溢出（outofmemory）",-1),a("p",null,"仅靠程序本身无法恢复和预防",-1),a("h4",{id:"exception类",tabindex:"-1"},[n("Exception类 "),a("a",{class:"header-anchor",href:"#exception类","aria-label":'Permalink to "Exception类"'},"​")],-1),a("p",null,"程序可以处理的异常",-1),a("p",null,"分为运行时异常和受检查时异常",-1),a("p",null,"运行时异常：RuntimeException 及其子类",-1),a("p",null,"数组索引越界异常 ArrayIndexOutOfBoundsException",-1),a("p",null,"空指针异常 NullPointerException",-1),a("p",null,"数字操作异常 ArithemeticException 10/0",-1),a("p",null,"类型转换异常 ClassCastException",-1),a("p",null,"数字转换异常 NumberFormatException",-1),a("p",null,"除RuntimeException 之外所有的异常： 编译时异常，主要起到提醒作用",-1),a("h4",{id:"运行时异常和受检异常的不同",tabindex:"-1"},[n("运行时异常和受检异常的不同 "),a("a",{class:"header-anchor",href:"#运行时异常和受检异常的不同","aria-label":'Permalink to "运行时异常和受检异常的不同"'},"​")],-1),a("p",null,"运⾏时异常：如：空指针异常、指定的类找不到、数组越界、⽅法传递参数错误、数据类型转换错误。可以编译通过，但是⼀运⾏就停⽌了，程序不会⾃⼰处理；",-1),a("p",null,"Nullpointerexception indexoutofboundsexception",-1),a("p",null,"受检查异常：要么⽤ try … catch… 捕获，要么⽤ throws 声明抛出，交给⽗类处理。",-1),a("p",null,"ioexception classnotfoundexception",-1),a("h3",{id:"_2、常见的异常类",tabindex:"-1"},[n("2、常见的异常类 "),a("a",{class:"header-anchor",href:"#_2、常见的异常类","aria-label":'Permalink to "2、常见的异常类"'},"​")],-1),a("p",null,"NullPointerException：当应⽤程序试图访问空对象时，则抛出该异常。",-1),a("p",null,"SQLException：提供关于数据库访问错误或其他错误信息的异常。",-1),a("p",null,"IndexOutOfBoundsException：指示某排序索引（例如对数组、字符串或向量的排序）超出范围时抛出。",-1),a("p",null,"FileNotFoundException：当试图打开指定路径名表示的⽂件失败时，抛出此异常。",-1),a("p",null,"IOException：当发⽣某种 I/O 异常时，抛出此异常。此类是失败或中断的 I/O 操作⽣成的异常的通⽤类。",-1),a("p",null,"ClassCastException：当试图将对象强制转换为不是实例的⼦类时，抛出该异常。",-1),a("p",null,"IllegalArgumentException：抛出的异常表明向⽅法传递了⼀个不合法或不正确的参数",-1),a("p",null,"RuntimeException：运行时异常",-1),a("p",null,"ClassNotFoundException：找不到对应的类 异常",-1),a("h4",{id:"",tabindex:"-1"},[a("a",{class:"header-anchor",href:"#","aria-label":'Permalink to ""'},"​")],-1),a("h3",{id:"_3-、throw和throws的区别",tabindex:"-1"},[n("3 、throw和throws的区别 "),a("a",{class:"header-anchor",href:"#_3-、throw和throws的区别","aria-label":'Permalink to "3 、throw和throws的区别"'},"​")],-1),a("p",null,"1、throw：在⽅法体内部，表示抛出异常，由⽅法体内部的语句处理；throw 是具体向外抛出异常的动作，所以它抛出的是⼀个异常实例；",-1),a("p",null,"2、throws：在⽅法声明后⾯，表示如果抛出异常，由该⽅法的调⽤者来进⾏异常的处理；表示出现异常的可能性，并不⼀定会发⽣这种异常。",-1),a("h3",{id:"_4、finally相关问题",tabindex:"-1"},[n("4、finally相关问题 "),a("a",{class:"header-anchor",href:"#_4、finally相关问题","aria-label":'Permalink to "4、finally相关问题"'},"​")],-1),a("h4",{id:"finally块中代码什么时候被执行",tabindex:"-1"},[n("finally块中代码什么时候被执行 "),a("a",{class:"header-anchor",href:"#finally块中代码什么时候被执行","aria-label":'Permalink to "finally块中代码什么时候被执行"'},"​")],-1),a("p",null,"一定会被执行，在return之前执行",-1),a("p",null,"如果 try-finally 或者 catch-finally 中都有 return，那么 finally 块中的 return 将会覆盖别处的 return 语句，最终返回到调⽤者那⾥的是 finally 中 return 的值。",-1),a("h4",{id:"finally是不是一定会被执行到",tabindex:"-1"},[n("finally是不是一定会被执行到 "),a("a",{class:"header-anchor",href:"#finally是不是一定会被执行到","aria-label":'Permalink to "finally是不是一定会被执行到"'},"​")],-1),a("p",null,"不一定。有两种情况",-1),a("p",null,"1、当程序进入try块之前就出现异常，会直接结束，不会执行finally块中的代码",-1),a("p",null,"2、当程序在try块中强制退出时也不会执行，比如try块中执行exit方法",-1),a("h3",{id:"_5、异常处理过程",tabindex:"-1"},[n("5、异常处理过程 "),a("a",{class:"header-anchor",href:"#_5、异常处理过程","aria-label":'Permalink to "5、异常处理过程"'},"​")],-1),a("p",null,"异常处理是程序出现错误时，避免程序崩溃的一种机制",-1),a("p",null,"java对异常的默认处理方式：向上抛出",-1),a("p",null,"默认处理流程：",-1),a("p",null,"1、程序运行时出现异常，会自动创建一个异常对象，并将其抛出",-1),a("p",null,"2、异常对象会被传递给调用栈的第一个异常处理程序",-1),a("p",null,"3、如果无法处理，则向上抛出。",-1),a("p",null,"4、如果所有的异常处理程序都无法处理该异常，则程序终止运行，并将异常信息输出到控制台",-1),a("h4",{id:"try-catch捕获异常",tabindex:"-1"},[n("try…catch捕获异常 "),a("a",{class:"header-anchor",href:"#try-catch捕获异常","aria-label":'Permalink to "try...catch捕获异常"'},"​")],-1),a("p",null,"好处：异常对象可以被捕获，后续的代码可以继续执行",-1),a("p",null,"格式：",-1),a("p",null,"try{",-1),a("p",null,"可能会出现异常的代码",-1),a("p",null,"}catch(异常名称 对象名){",-1),a("p",null,"异常的处理方案",-1),a("p",null,"}",-1),a("p",null,"执行流程：",-1),a("p",null,"1、执行try{}中的代码，看是否有异常对象产生",-1),a("p",null,"2、没有：catch就不会捕获，后续代码继续执行",-1),a("p",null,"3、 有：catch捕获异常对象，执行catch{}中的处理方案，后续代码继续执行",-1),a("h3",{id:"_6、外中断和异常的区别",tabindex:"-1"},[n("6、外中断和异常的区别 "),a("a",{class:"header-anchor",href:"#_6、外中断和异常的区别","aria-label":'Permalink to "6、外中断和异常的区别"'},"​")],-1),a("p",null,"外中断是指由CPU执行指令以外的事件引起，如IO完成中断，表示设备输入//输出处理已经完成，处理器能发送下一个输入/输出请求。",-1),a("p",null,"而异常时由CPU执行指令的内部事件引起",-1)])),"main-header":e(()=>[t(l.$slots,"main-header")]),"main-header-after":e(()=>[t(l.$slots,"main-header-after")]),"main-nav":e(()=>[t(l.$slots,"main-nav")]),"main-content-before":e(()=>[t(l.$slots,"main-content-before")]),"main-content":e(()=>[t(l.$slots,"main-content")]),"main-content-after":e(()=>[t(l.$slots,"main-content-after")]),"main-nav-before":e(()=>[t(l.$slots,"main-nav-before")]),"main-nav-after":e(()=>[t(l.$slots,"main-nav-after")]),comment:e(()=>[t(l.$slots,"comment")]),footer:e(()=>[t(l.$slots,"footer")]),aside:e(()=>[t(l.$slots,"aside")]),"aside-custom":e(()=>[t(l.$slots,"aside-custom")]),default:e(()=>[t(l.$slots,"default")]),_:3},8,["frontmatter"])}}};export{V as default,_ as usePageData};
